Workbook

Sheet RESULT
A1: {=_xll.DUCKDB.INFO()} -> Add-in version: 1.9.0 DuckDB version: v2.0.0
A3: Test | B3: Number of Test Cases | C3: Passed
A4: VALUES | B4: =COUNT(VALUES!A2:A35) -> 34 | C4: =COUNTIF(VALUES!F2:F35,"PASS") -> 34
A5: PARAMETER BINDING | B5: =COUNT(BIND!A2:A7) -> 6 | C5: =COUNTIF(BIND!G2:G7,"PASS") -> 6
A6: INFERENCE_1 | B6: =COUNT(INFERENCE_1!A2:A70) -> 69 | C6: =COUNTIFS(INFERENCE_1!$G$2:$G$70,"PASS",INFERENCE_1!$K$2:$K$70,"PASS") -> 69
A7: INFERENCE_2 | B7: =COUNT(INFERENCE_2!A2:A45) -> 21 | C7: =COUNTIFS(INFERENCE_2!G2:G45,"PASS") -> 21
A8: CONVERT | B8: =COUNT(CONVERT!A2:A113) -> 56 | C8: =COUNTIF(CONVERT!G2:G113,"PASS") -> 56
A9: XLRANGE OPTIONS | B9: =COUNT('XLRANGE OPTIONS'!A12:A71) -> 13 | C9: =COUNTIF('XLRANGE OPTIONS'!G12:G71,"PASS") -> 13
A10: SCALAR FUNCTIONS | B10: =COUNT('SCALAR FUNCS'!A2:A4) -> 3 | C10: =COUNTIF('SCALAR FUNCS'!G2:G4,"PASS") -> 3
A11: EXECX-A-AX-ASYNC | B11: =COUNT('EXECX-A-AX-ASYNC'!A2:A8) -> 7 | C11: =COUNTIF('EXECX-A-AX-ASYNC'!G2:G8,"PASS") -> 7
A12: Total | B12: =SUM(B4:B11) -> 209 | C12: =SUM(C4:C11) -> 209
A15: ***Press Ctrl + Alt + F9 to recalculate***

Sheet VALUES
A1: ID | B1: Testcase | C1: SQL | D1: Expected Result | E1: Actual Result | F1: Test result
A2: 1 | B2: TINYINT | C2: select 127::tinyint | D2: 127 | E2: {=INDEX(_xll.DUCKDB.EXEC(C2),2)} -> 127 | F2: =IF(ISNA(D2),IF(ISNA(E2),"PASS","FAIL"),IFERROR(IF(D2=E2,"PASS","FAIL"),"FAIL")) -> PASS
A3: 2 | B3: TINYINT | C3: select (-128)::tinyint | D3: -128 | E3: {=INDEX(_xll.DUCKDB.EXEC(C3),2)} -> -128 | F3: =IF(ISNA(D3),IF(ISNA(E3),"PASS","FAIL"),IFERROR(IF(D3=E3,"PASS","FAIL"),"FAIL")) -> PASS
A4: 3 | B4: UTINYINT | C4: select 255::utinyint | D4: 255 | E4: {=INDEX(_xll.DUCKDB.EXEC(C4),2)} -> 255 | F4: =IF(ISNA(D4),IF(ISNA(E4),"PASS","FAIL"),IFERROR(IF(D4=E4,"PASS","FAIL"),"FAIL")) -> PASS
A5: 4 | B5: SMALLINT | C5: select 32767::smallint | D5: 32767 | E5: {=INDEX(_xll.DUCKDB.EXEC(C5),2)} -> 32767 | F5: =IF(ISNA(D5),IF(ISNA(E5),"PASS","FAIL"),IFERROR(IF(D5=E5,"PASS","FAIL"),"FAIL")) -> PASS
A6: 5 | B6: SMALLINT | C6: select (-32768)::smallint | D6: -32768 | E6: {=INDEX(_xll.DUCKDB.EXEC(C6),2)} -> -32768 | F6: =IF(ISNA(D6),IF(ISNA(E6),"PASS","FAIL"),IFERROR(IF(D6=E6,"PASS","FAIL"),"FAIL")) -> PASS
A7: 6 | B7: USMALLINT | C7: select 65535::usmallint | D7: 65535 | E7: {=INDEX(_xll.DUCKDB.EXEC(C7),2)} -> 65535 | F7: =IF(ISNA(D7),IF(ISNA(E7),"PASS","FAIL"),IFERROR(IF(D7=E7,"PASS","FAIL"),"FAIL")) -> PASS
A8: 7 | B8: INTEGER | C8: select 2147483647::integer | D8: 2147483647 | E8: {=INDEX(_xll.DUCKDB.EXEC(C8),2)} -> 2147483647 | F8: =IF(ISNA(D8),IF(ISNA(E8),"PASS","FAIL"),IFERROR(IF(D8=E8,"PASS","FAIL"),"FAIL")) -> PASS
A9: 8 | B9: INTEGER | C9: select (-2147483648)::integer | D9: -2147483648 | E9: {=INDEX(_xll.DUCKDB.EXEC(C9),2)} -> -2147483648 | F9: =IF(ISNA(D9),IF(ISNA(E9),"PASS","FAIL"),IFERROR(IF(D9=E9,"PASS","FAIL"),"FAIL")) -> PASS
A10: 9 | B10: UINTEGER | C10: select 4294967295::uinteger | D10: 4294967295 | E10: {=INDEX(_xll.DUCKDB.EXEC(C10),2)} -> 4294967295 | F10: =IF(ISNA(D10),IF(ISNA(E10),"PASS","FAIL"),IFERROR(IF(D10=E10,"PASS","FAIL"),"FAIL")) -> PASS
A11: 10 | B11: BIGINT | C11: select 9223372036854775807::bigint | D11: 9.223372e+18 | E11: {=INDEX(_xll.DUCKDB.EXEC(C11),2)} -> 9.223372e+18 | F11: =IF(ISNA(D11),IF(ISNA(E11),"PASS","FAIL"),IFERROR(IF(D11=E11,"PASS","FAIL"),"FAIL")) -> PASS
A12: 11 | B12: BIGINT | C12: select (-9223372036854775808)::bigint | D12: -9.223372e+18 | E12: {=INDEX(_xll.DUCKDB.EXEC(C12),2)} -> -9.223372e+18 | F12: =IF(ISNA(D12),IF(ISNA(E12),"PASS","FAIL"),IFERROR(IF(D12=E12,"PASS","FAIL"),"FAIL")) -> PASS
A13: 12 | B13: UBIGINT | C13: select 18446744073709551615::ubigint | D13: 1.8446744e+19 | E13: {=INDEX(_xll.DUCKDB.EXEC(C13),2)} -> 1.8446744e+19 | F13: =IF(ISNA(D13),IF(ISNA(E13),"PASS","FAIL"),IFERROR(IF(D13=E13,"PASS","FAIL"),"FAIL")) -> PASS
... A16: 15 | B16: UHUGEINT | C16: select 18446744073709551615::uhugeint | D16: 1.8446744e+19 | E16: {=INDEX(_xll.DUCKDB.EXEC(C16),2)} -> 1.8446744e+19 | F16: =IF(ISNA(D16),IF(ISNA(E16),"PASS","FAIL"),IFERROR(IF(D16=E16,"PASS","FAIL"),"FAIL")) -> PASS
A17: 16 | B17: BOOLEAN | C17: select true | D17: TRUE | E17: {=INDEX(_xll.DUCKDB.EXEC(C17),2)} -> TRUE | F17: =IF(ISNA(D17),IF(ISNA(E17),"PASS","FAIL"),IFERROR(IF(D17=E17,"PASS","FAIL"),"FAIL")) -> PASS
A18: 17 | B18: BOOLEAN | C18: select false | D18: FALSE | E18: {=INDEX(_xll.DUCKDB.EXEC(C18),2)} -> FALSE | F18: =IF(ISNA(D18),IF(ISNA(E18),"PASS","FAIL"),IFERROR(IF(D18=E18,"PASS","FAIL"),"FAIL")) -> PASS
A19: 18 | B19: VARCHAR | C19: select 'abc' | D19: abc | E19: {=INDEX(_xll.DUCKDB.EXEC(C19),2)} -> abc | F19: =IF(ISNA(D19),IF(ISNA(E19),"PASS","FAIL"),IFERROR(IF(D19=E19,"PASS","FAIL"),"FAIL")) -> PASS
A20: 19 | B20: FLOAT | C20: select 1.2::float | D20: 1.2 | E20: {=INDEX(_xll.DUCKDB.EXEC(C20),2)} -> 1.2 | F20: =IF(ISNA(D20),IF(ISNA(E20),"PASS","FAIL"),IFERROR(IF(ABS(D20-E20)<0.0000001,"PASS","FAIL"),"FAIL")) -> PASS
A21: 20 | B21: DOUBLE | C21: select 1.2::double | D21: 1.2 | E21: {=INDEX(_xll.DUCKDB.EXEC(C21),2)} -> 1.2 | F21: =IF(ISNA(D21),IF(ISNA(E21),"PASS","FAIL"),IFERROR(IF(D21=E21,"PASS","FAIL"),"FAIL")) -> PASS
A22: 21 | B22: SMALLINT BASED DECIMAL | C22: select 1.2::decimal(4, 2) | D22: 1.2 | E22: {=INDEX(_xll.DUCKDB.EXEC(C22),2)} -> 1.2 | F22: =IF(ISNA(D22),IF(ISNA(E22),"PASS","FAIL"),IFERROR(IF(D22=E22,"PASS","FAIL"),"FAIL")) -> PASS
A23: 22 | B23: INTEGER BASED DECIMAL | C23: select 1.2::decimal(9, 2) | D23: 1.2 | E23: {=INDEX(_xll.DUCKDB.EXEC(C23),2)} -> 1.2 | F23: =IF(ISNA(D23),IF(ISNA(E23),"PASS","FAIL"),IFERROR(IF(D23=E23,"PASS","FAIL"),"FAIL")) -> PASS
A24: 23 | B24: BIGINT BASED DECIMAL | C24: select 1.2::decimal(18, 2) | D24: 1.2 | E24: {=INDEX(_xll.DUCKDB.EXEC(C24),2)} -> 1.2 | F24: =IF(ISNA(D24),IF(ISNA(E24),"PASS","FAIL"),IFERROR(IF(D24=E24,"PASS","FAIL"),"FAIL")) -> PASS
A25: 24 | B25: HUGEINT BASED DECIMAL | C25: select 1.2::decimal(38, 2) | D25: 1.2 | E25: {=INDEX(_xll.DUCKDB.EXEC(C25),2)} -> 1.2 | F25: =IF(ISNA(D25),IF(ISNA(E25),"PASS","FAIL"),IFERROR(IF(D25=E25,"PASS","FAIL"),"FAIL")) -> PASS
A26: 25 | B26: DATE | C26: select '2026-12-31'::date | D26: 46387 | E26: {=INDEX(_xll.DUCKDB.EXEC(C26),2)} -> 46387 | F26: =IF(ISNA(D26),IF(ISNA(E26),"PASS","FAIL"),IFERROR(IF(D26=E26,"PASS","FAIL"),"FAIL")) -> PASS
A27: 26 | B27: TIME | C27: select '09:30:45'::time | D27: 0.39635417 | E27: {=INDEX(_xll.DUCKDB.EXEC(C27),2)} -> 0.39635417 | F27: =IF(ISNA(D27),IF(ISNA(E27),"PASS","FAIL"),IFERROR(IF(D27=E27,"PASS","FAIL"),"FAIL")) -> PASS
A28: 27 | B28: TIME WITH TIME ZONE | C28: select '09:30:45+07:00'::time with time zone | D28: 0.39635417 | E28: {=INDEX(_xll.DUCKDB.EXEC(C28),2)} -> 0.39635417 | F28: =IF(ISNA(D28),IF(ISNA(E28),"PASS","FAIL"),IFERROR(IF(D28=E28,"PASS","FAIL"),"FAIL")) -> PASS
A29: 28 | B29: TIMESTAMP | C29: select '2026-12-31 09:30:45'::timestamp | D29: 46387.396 | E29: {=INDEX(_xll.DUCKDB.EXEC(C29),2)} -> 46387.396 | F29: =IF(ISNA(D29),IF(ISNA(E29),"PASS","FAIL"),IFERROR(IF(D29=E29,"PASS","FAIL"),"FAIL")) -> PASS
A30: 29 | B30: TIMESTAMP WITH TIME ZONE | C30: select '2026-12-31 09:30:45+07:00'::timestamp with time zone | D30: 46387.105 | E30: {=INDEX(_xll.DUCKDB.EXEC(C30),2)} -> 46387.105 | F30: =IF(ISNA(D30),IF(ISNA(E30),"PASS","FAIL"),IFERROR(IF(D30=E30,"PASS","FAIL"),"FAIL")) -> PASS
A31: 30 | B31: TIMESTAMP_S | C31: select '2026-12-31 09:30:45'::timestamp_s | D31: 46387.396 | E31: {=INDEX(_xll.DUCKDB.EXEC(C31),2)} -> 46387.396 | F31: =IF(ISNA(D31),IF(ISNA(E31),"PASS","FAIL"),IFERROR(IF(D31=E31,"PASS","FAIL"),"FAIL")) -> PASS
A32: 31 | B32: TIMESTAMP_MS | C32: select '2026-12-31 09:30:45'::timestamp_ms | D32: 46387.396 | E32: {=INDEX(_xll.DUCKDB.EXEC(C32),2)} -> 46387.396 | F32: =IF(ISNA(D32),IF(ISNA(E32),"PASS","FAIL"),IFERROR(IF(D32=E32,"PASS","FAIL"),"FAIL")) -> PASS
A33: 32 | B33: TIMESTAMP_NS | C33: select '2026-12-31 09:30:45'::timestamp_ns | D33: 46387.396 | E33: {=INDEX(_xll.DUCKDB.EXEC(C33),2)} -> 46387.396 | F33: =IF(ISNA(D33),IF(ISNA(E33),"PASS","FAIL"),IFERROR(IF(D33=E33,"PASS","FAIL"),"FAIL")) -> PASS
A34: 33 | B34: NULL | C34: select null | D34: #N/A | E34: {=INDEX(_xll.DUCKDB.EXEC(C34),2)} -> #N/A | F34: =IF(ISNA(D34),IF(ISNA(E34),"PASS","FAIL"),IFERROR(IF(D34=E34,"PASS","FAIL"),"FAIL")) -> PASS
A35: 34 | B35: OTHER TYPES | C35: select array_value(1, 2, 3) as my_column; | D35: Error | E35: {=_xll.DUCKDB.EXEC(C35)} -> Error fetching data: Column my_column: Unsupported DuckDB type. Convert the value to VARCHAR before returning it to Excel. | F35: =IF(ISNA(D35),IF(ISNA(E35),"PASS","FAIL"),IFERROR(IF(D35=LEFT(E35,LEN(D35)),"PASS","FAIL"),"FAIL")) -> PASS
C39: {=_xll.DUCKDB.EXEC(C34)} -> NULL
C40: #N/A

Sheet BIND
A1: ID | B1: Test Case | C1: Excel Value | D1: SQL | E1: Expected Result | F1: Actual Result | G1: Test Result
A2: 1 | B2: NUMBER | C2: 1 | D2: select ? | E2: 1 | F2: {=INDEX(_xll.DUCKDB.EXEC($D$2,C2),2)} -> 1 | G2: =IF(F2=E2,"PASS","FAIL") -> PASS
A3: 2 | B3: NUMBER | C3: 1.2 | E3: 1.2 | F3: {=INDEX(_xll.DUCKDB.EXEC($D$2,C3),2)} -> 1.2 | G3: =IF(F3=E3,"PASS","FAIL") -> PASS
A4: 3 | B4: VARCHAR | C4: abc | E4: abc | F4: {=INDEX(_xll.DUCKDB.EXEC($D$2,C4),2)} -> abc | G4: =IF(F4=E4,"PASS","FAIL") -> PASS
A5: 4 | B5: BOOLEAN | C5: FALSE | E5: FALSE | F5: {=INDEX(_xll.DUCKDB.EXEC($D$2,C5),2)} -> FALSE | G5: =IF(F5=E5,"PASS","FAIL") -> PASS
A6: 5 | B6: EMPTY | E6: #N/A | F6: {=INDEX(_xll.DUCKDB.EXEC($D$2,C6),2)} -> #N/A | G6: =IF(ISNA(E6),IF(ISNA(F6),"PASS","FAIL"),IFERROR(IF(E6=LEFT(F6,LEN(E6)),"PASS","FAIL"),"FAIL")) -> PASS
A7: 6 | B7: ERROR | C7: =1/0 -> #DIV/0! | E7: Error | F7: {=_xll.DUCKDB.EXEC($D$2,C7)} -> Error: Parameter binding failed. | G7: =IF(ISNA(E7),IF(ISNA(F7),"PASS","FAIL"),IFERROR(IF(E7=LEFT(F7,LEN(E7)),"PASS","FAIL"),"FAIL")) -> PASS

Sheet INFERENCE_1
A1: ID | B1: Test case | C1: Excel Value | D1: Inferred Type Test SQL | E1: Expected Inferred Type | F1: Actual Inferred Type | G1: Inferred Type Test Result | H1: Value Test SQL | I1: Expected Value | J1: Actual Value | K1: Value Test Result
A2: 1 | B2: Integer | C2: 1 | D2: select column_type from (describe (from xlrange(1, header=false, sample=1))) where column_name = 'column_1'; | E2: INTEGER | F2: {=INDEX(_xll.DUCKDB.EXEC($D$2,B2:C2),2)} -> INTEGER | G2: =IF(E2=F2,"PASS","FAIL") -> PASS | H2: select column_1 from xlrange(1, header=false, sample=1) | I2: =C2 -> 1 | J2: {=INDEX(_xll.DUCKDB.EXEC($H$2,B2:C2),2)} -> 1 | K2: =IF(ISNA(I2),IF(ISNA(J2),"PASS","FAIL"),IFERROR(IF(I2=J2,"PASS","FAIL"),"FAIL")) -> PASS | N2: {=_xll.DUCKDB.EXEC($H$2,B2:C2)} -> column_1
A3: 2 | B3: Integer | C3: -1 | E3: INTEGER | F3: {=INDEX(_xll.DUCKDB.EXEC($D$2,B3:C3),2)} -> INTEGER | G3: =IF(E3=F3,"PASS","FAIL") -> PASS | I3: =C3 -> -1 | J3: {=INDEX(_xll.DUCKDB.EXEC($H$2,B3:C3),2)} -> -1 | K3: =IF(ISNA(I3),IF(ISNA(J3),"PASS","FAIL"),IFERROR(IF(I3=J3,"PASS","FAIL"),"FAIL")) -> PASS | N3: 1
A4: 3 | B4: Integer | C4: 2 | E4: INTEGER | F4: {=INDEX(_xll.DUCKDB.EXEC($D$2,B4:C4),2)} -> INTEGER | G4: =IF(E4=F4,"PASS","FAIL") -> PASS | I4: =C4 -> 2 | J4: {=INDEX(_xll.DUCKDB.EXEC($H$2,B4:C4),2)} -> 2 | K4: =IF(ISNA(I4),IF(ISNA(J4),"PASS","FAIL"),IFERROR(IF(I4=J4,"PASS","FAIL"),"FAIL")) -> PASS | N4: select column_1 from xlrange(1, header=false, sample=1)
A5: 4 | B5: Integer | C5: -2 | E5: INTEGER | F5: {=INDEX(_xll.DUCKDB.EXEC($D$2,B5:C5),2)} -> INTEGER | G5: =IF(E5=F5,"PASS","FAIL") -> PASS | I5: =C5 -> -2 | J5: {=INDEX(_xll.DUCKDB.EXEC($H$2,B5:C5),2)} -> -2 | K5: =IF(ISNA(I5),IF(ISNA(J5),"PASS","FAIL"),IFERROR(IF(I5=J5,"PASS","FAIL"),"FAIL")) -> PASS
A6: 5 | B6: Integer stored as text | C6: 1 | E6: INTEGER | F6: {=INDEX(_xll.DUCKDB.EXEC($D$2,B6:C6),2)} -> INTEGER | G6: =IF(E6=F6,"PASS","FAIL") -> PASS | I6: 1 | J6: {=INDEX(_xll.DUCKDB.EXEC($H$2,B6:C6),2)} -> 1 | K6: =IF(ISNA(I6),IF(ISNA(J6),"PASS","FAIL"),IFERROR(IF(I6=J6,"PASS","FAIL"),"FAIL")) -> PASS | N6: {=_xll.DUCKDB.EXEC(N4,B2:C2)} -> column_1
A7: 6 | B7: Integer stored as text | C7: -1 | E7: INTEGER | F7: {=INDEX(_xll.DUCKDB.EXEC($D$2,B7:C7),2)} -> INTEGER | G7: =IF(E7=F7,"PASS","FAIL") -> PASS | I7: -1 | J7: {=INDEX(_xll.DUCKDB.EXEC($H$2,B7:C7),2)} -> -1 | K7: =IF(ISNA(I7),IF(ISNA(J7),"PASS","FAIL"),IFERROR(IF(I7=J7,"PASS","FAIL"),"FAIL")) -> PASS | N7: 1
A8: 7 | B8: Integer stored as text | C8: 1.0 | E8: INTEGER | F8: {=INDEX(_xll.DUCKDB.EXEC($D$2,B8:C8),2)} -> INTEGER | G8: =IF(E8=F8,"PASS","FAIL") -> PASS | I8: 1 | J8: {=INDEX(_xll.DUCKDB.EXEC($H$2,B8:C8),2)} -> 1 | K8: =IF(ISNA(I8),IF(ISNA(J8),"PASS","FAIL"),IFERROR(IF(I8=J8,"PASS","FAIL"),"FAIL")) -> PASS
A9: 8 | B9: Integer stored as text | C9: -1.0 | E9: INTEGER | F9: {=INDEX(_xll.DUCKDB.EXEC($D$2,B9:C9),2)} -> INTEGER | G9: =IF(E9=F9,"PASS","FAIL") -> PASS | I9: -1 | J9: {=INDEX(_xll.DUCKDB.EXEC($H$2,B9:C9),2)} -> -1 | K9: =IF(ISNA(I9),IF(ISNA(J9),"PASS","FAIL"),IFERROR(IF(I9=J9,"PASS","FAIL"),"FAIL")) -> PASS
A10: 9 | B10: Integer stored as text | C10: 1e1 | E10: INTEGER | F10: {=INDEX(_xll.DUCKDB.EXEC($D$2,B10:C10),2)} -> INTEGER | G10: =IF(E10=F10,"PASS","FAIL") -> PASS | I10: 10 | J10: {=INDEX(_xll.DUCKDB.EXEC($H$2,B10:C10),2)} -> 10 | K10: =IF(ISNA(I10),IF(ISNA(J10),"PASS","FAIL"),IFERROR(IF(I10=J10,"PASS","FAIL"),"FAIL")) -> PASS
A11: 10 | B11: Integer stored as text | C11: -1e1 | E11: INTEGER | F11: {=INDEX(_xll.DUCKDB.EXEC($D$2,B11:C11),2)} -> INTEGER | G11: =IF(E11=F11,"PASS","FAIL") -> PASS | I11: -10 | J11: {=INDEX(_xll.DUCKDB.EXEC($H$2,B11:C11),2)} -> -10 | K11: =IF(ISNA(I11),IF(ISNA(J11),"PASS","FAIL"),IFERROR(IF(I11=J11,"PASS","FAIL"),"FAIL")) -> PASS
A12: 11 | B12: Integer stored as text with leading and trailing space | C12: 1 | E12: INTEGER | F12: {=INDEX(_xll.DUCKDB.EXEC($D$2,B12:C12),2)} -> INTEGER | G12: =IF(E12=F12,"PASS","FAIL") -> PASS | I12: 1 | J12: {=INDEX(_xll.DUCKDB.EXEC($H$2,B12:C12),2)} -> 1 | K12: =IF(ISNA(I12),IF(ISNA(J12),"PASS","FAIL"),IFERROR(IF(I12=J12,"PASS","FAIL"),"FAIL")) -> PASS
A13: 12 | B13: Integer stored as text with leading and trailing space | C13: -1 | E13: INTEGER | F13: {=INDEX(_xll.DUCKDB.EXEC($D$2,B13:C13),2)} -> INTEGER | G13: =IF(E13=F13,"PASS","FAIL") -> PASS | I13: -1 | J13: {=INDEX(_xll.DUCKDB.EXEC($H$2,B13:C13),2)} -> -1 | K13: =IF(ISNA(I13),IF(ISNA(J13),"PASS","FAIL"),IFERROR(IF(I13=J13,"PASS","FAIL"),"FAIL")) -> PASS
A14: 13 | B14: Integer stored as text with leading and trailing space | C14: 1.0 | E14: INTEGER | F14: {=INDEX(_xll.DUCKDB.EXEC($D$2,B14:C14),2)} -> INTEGER | G14: =IF(E14=F14,"PASS","FAIL") -> PASS | I14: 1 | J14: {=INDEX(_xll.DUCKDB.EXEC($H$2,B14:C14),2)} -> 1 | K14: =IF(ISNA(I14),IF(ISNA(J14),"PASS","FAIL"),IFERROR(IF(I14=J14,"PASS","FAIL"),"FAIL")) -> PASS
A15: 14 | B15: Integer stored as text with leading and trailing space | C15: -1.0 | E15: INTEGER | F15: {=INDEX(_xll.DUCKDB.EXEC($D$2,B15:C15),2)} -> INTEGER | G15: =IF(E15=F15,"PASS","FAIL") -> PASS | I15: -1 | J15: {=INDEX(_xll.DUCKDB.EXEC($H$2,B15:C15),2)} -> -1 | K15: =IF(ISNA(I15),IF(ISNA(J15),"PASS","FAIL"),IFERROR(IF(I15=J15,"PASS","FAIL"),"FAIL")) -> PASS
A16: 15 | B16: Integer stored as text with leading and trailing space | C16: 1e1 | E16: INTEGER | F16: {=INDEX(_xll.DUCKDB.EXEC($D$2,B16:C16),2)} -> INTEGER | G16: =IF(E16=F16,"PASS","FAIL") -> PASS | I16: 10 | J16: {=INDEX(_xll.DUCKDB.EXEC($H$2,B16:C16),2)} -> 10 | K16: =IF(ISNA(I16),IF(ISNA(J16),"PASS","FAIL"),IFERROR(IF(I16=J16,"PASS","FAIL"),"FAIL")) -> PASS
A17: 16 | B17: Integer stored as text with leading and trailing space | C17: -1e1 | E17: INTEGER | F17: {=INDEX(_xll.DUCKDB.EXEC($D$2,B17:C17),2)} -> INTEGER | G17: =IF(E17=F17,"PASS","FAIL") -> PASS | I17: -10 | J17: {=INDEX(_xll.DUCKDB.EXEC($H$2,B17:C17),2)} -> -10 | K17: =IF(ISNA(I17),IF(ISNA(J17),"PASS","FAIL"),IFERROR(IF(I17=J17,"PASS","FAIL"),"FAIL")) -> PASS
A18: 17 | B18: Double | C18: 1.2 | E18: DOUBLE | F18: {=INDEX(_xll.DUCKDB.EXEC($D$2,B18:C18),2)} -> DOUBLE | G18: =IF(E18=F18,"PASS","FAIL") -> PASS | I18: =C18 -> 1.2 | J18: {=INDEX(_xll.DUCKDB.EXEC($H$2,B18:C18),2)} -> 1.2 | K18: =IF(ISNA(I18),IF(ISNA(J18),"PASS","FAIL"),IFERROR(IF(I18=J18,"PASS","FAIL"),"FAIL")) -> PASS
A19: 18 | B19: Double | C19: -1.2 | E19: DOUBLE | F19: {=INDEX(_xll.DUCKDB.EXEC($D$2,B19:C19),2)} -> DOUBLE | G19: =IF(E19=F19,"PASS","FAIL") -> PASS | I19: =C19 -> -1.2 | J19: {=INDEX(_xll.DUCKDB.EXEC($H$2,B19:C19),2)} -> -1.2 | K19: =IF(ISNA(I19),IF(ISNA(J19),"PASS","FAIL"),IFERROR(IF(I19=J19,"PASS","FAIL"),"FAIL")) -> PASS
A20: 19 | B20: Double stored as text | C20: 1.2 | E20: DOUBLE | F20: {=INDEX(_xll.DUCKDB.EXEC($D$2,B20:C20),2)} -> DOUBLE | G20: =IF(E20=F20,"PASS","FAIL") -> PASS | I20: 1.2 | J20: {=INDEX(_xll.DUCKDB.EXEC($H$2,B20:C20),2)} -> 1.2 | K20: =IF(ISNA(I20),IF(ISNA(J20),"PASS","FAIL"),IFERROR(IF(I20=J20,"PASS","FAIL"),"FAIL")) -> PASS
A21: 20 | B21: Double stored as text | C21: -1.2 | E21: DOUBLE | F21: {=INDEX(_xll.DUCKDB.EXEC($D$2,B21:C21),2)} -> DOUBLE | G21: =IF(E21=F21,"PASS","FAIL") -> PASS | I21: -1.2 | J21: {=INDEX(_xll.DUCKDB.EXEC($H$2,B21:C21),2)} -> -1.2 | K21: =IF(ISNA(I21),IF(ISNA(J21),"PASS","FAIL"),IFERROR(IF(I21=J21,"PASS","FAIL"),"FAIL")) -> PASS
A22: 21 | B22: Double stored as text with leading and trailing space | C22: 1.2 | E22: DOUBLE | F22: {=INDEX(_xll.DUCKDB.EXEC($D$2,B22:C22),2)} -> DOUBLE | G22: =IF(E22=F22,"PASS","FAIL") -> PASS | I22: 1.2 | J22: {=INDEX(_xll.DUCKDB.EXEC($H$2,B22:C22),2)} -> 1.2 | K22: =IF(ISNA(I22),IF(ISNA(J22),"PASS","FAIL"),IFERROR(IF(I22=J22,"PASS","FAIL"),"FAIL")) -> PASS
A23: 22 | B23: Double stored as text with leading and trailing space | C23: -1.2 | E23: DOUBLE | F23: {=INDEX(_xll.DUCKDB.EXEC($D$2,B23:C23),2)} -> DOUBLE | G23: =IF(E23=F23,"PASS","FAIL") -> PASS | I23: -1.2 | J23: {=INDEX(_xll.DUCKDB.EXEC($H$2,B23:C23),2)} -> -1.2 | K23: =IF(ISNA(I23),IF(ISNA(J23),"PASS","FAIL"),IFERROR(IF(I23=J23,"PASS","FAIL"),"FAIL")) -> PASS
A24: 23 | B24: Double stored as text with leading and trailing space | C24: 1.2e-2 | E24: DOUBLE | F24: {=INDEX(_xll.DUCKDB.EXEC($D$2,B24:C24),2)} -> DOUBLE | G24: =IF(E24=F24,"PASS","FAIL") -> PASS | I24: 0.012 | J24: {=INDEX(_xll.DUCKDB.EXEC($H$2,B24:C24),2)} -> 0.012 | K24: =IF(ISNA(I24),IF(ISNA(J24),"PASS","FAIL"),IFERROR(IF(I24=J24,"PASS","FAIL"),"FAIL")) -> PASS
A25: 24 | B25: Double stored as text with leading and trailing space | C25: -1.2e-2 | E25: DOUBLE | F25: {=INDEX(_xll.DUCKDB.EXEC($D$2,B25:C25),2)} -> DOUBLE | G25: =IF(E25=F25,"PASS","FAIL") -> PASS | I25: -0.012 | J25: {=INDEX(_xll.DUCKDB.EXEC($H$2,B25:C25),2)} -> -0.012 | K25: =IF(ISNA(I25),IF(ISNA(J25),"PASS","FAIL"),IFERROR(IF(I25=J25,"PASS","FAIL"),"FAIL")) -> PASS
A26: 25 | B26: Number over INT32 limit | C26: 2147483648 | E26: DOUBLE | F26: {=INDEX(_xll.DUCKDB.EXEC($D$2,B26:C26),2)} -> DOUBLE | G26: =IF(E26=F26,"PASS","FAIL") -> PASS | I26: =C26 -> 2147483648 | J26: {=INDEX(_xll.DUCKDB.EXEC($H$2,B26:C26),2)} -> 2147483648 | K26: =IF(ISNA(I26),IF(ISNA(J26),"PASS","FAIL"),IFERROR(IF(I26=J26,"PASS","FAIL"),"FAIL")) -> PASS
A27: 26 | B27: Number over INT32 limit | C27: -2147483649 | E27: DOUBLE | F27: {=INDEX(_xll.DUCKDB.EXEC($D$2,B27:C27),2)} -> DOUBLE | G27: =IF(E27=F27,"PASS","FAIL") -> PASS | I27: =C27 -> -2147483649 | J27: {=INDEX(_xll.DUCKDB.EXEC($H$2,B27:C27),2)} -> -2147483649 | K27: =IF(ISNA(I27),IF(ISNA(J27),"PASS","FAIL"),IFERROR(IF(I27=J27,"PASS","FAIL"),"FAIL")) -> PASS
A28: 27 | B28: Number over INT32 limit with leading and trailing space | C28: 2147483648 | E28: DOUBLE | F28: {=INDEX(_xll.DUCKDB.EXEC($D$2,B28:C28),2)} -> DOUBLE | G28: =IF(E28=F28,"PASS","FAIL") -> PASS | I28: 2147483648 | J28: {=INDEX(_xll.DUCKDB.EXEC($H$2,B28:C28),2)} -> 2147483648 | K28: =IF(ISNA(I28),IF(ISNA(J28),"PASS","FAIL"),IFERROR(IF(I28=J28,"PASS","FAIL"),"FAIL")) -> PASS
A29: 28 | B29: Number over INT32 limit with leading and trailing space | C29: -2147483649 | E29: DOUBLE | F29: {=INDEX(_xll.DUCKDB.EXEC($D$2,B29:C29),2)} -> DOUBLE | G29: =IF(E29=F29,"PASS","FAIL") -> PASS | I29: -2147483649 | J29: {=INDEX(_xll.DUCKDB.EXEC($H$2,B29:C29),2)} -> -2147483649 | K29: =IF(ISNA(I29),IF(ISNA(J29),"PASS","FAIL"),IFERROR(IF(I29=J29,"PASS","FAIL"),"FAIL")) -> PASS
A30: 29 | B30: True/false | C30: TRUE | E30: BOOLEAN | F30: {=INDEX(_xll.DUCKDB.EXEC($D$2,B30:C30),2)} -> BOOLEAN | G30: =IF(E30=F30,"PASS","FAIL") -> PASS | I30: =C30 -> TRUE | J30: {=INDEX(_xll.DUCKDB.EXEC($H$2,B30:C30),2)} -> TRUE | K30: =IF(ISNA(I30),IF(ISNA(J30),"PASS","FAIL"),IFERROR(IF(I30=J30,"PASS","FAIL"),"FAIL")) -> PASS
A31: 30 | B31: True/false | C31: FALSE | E31: BOOLEAN | F31: {=INDEX(_xll.DUCKDB.EXEC($D$2,B31:C31),2)} -> BOOLEAN | G31: =IF(E31=F31,"PASS","FAIL") -> PASS | I31: =C31 -> FALSE | J31: {=INDEX(_xll.DUCKDB.EXEC($H$2,B31:C31),2)} -> FALSE | K31: =IF(ISNA(I31),IF(ISNA(J31),"PASS","FAIL"),IFERROR(IF(I31=J31,"PASS","FAIL"),"FAIL")) -> PASS
A32: 31 | B32: True/false in text | C32: TRUE | E32: BOOLEAN | F32: {=INDEX(_xll.DUCKDB.EXEC($D$2,B32:C32),2)} -> BOOLEAN | G32: =IF(E32=F32,"PASS","FAIL") -> PASS | I32: TRUE | J32: {=INDEX(_xll.DUCKDB.EXEC($H$2,B32:C32),2)} -> TRUE | K32: =IF(ISNA(I32),IF(ISNA(J32),"PASS","FAIL"),IFERROR(IF(I32=J32,"PASS","FAIL"),"FAIL")) -> PASS
A33: 32 | B33: True/false in text | C33: FALSE | E33: BOOLEAN | F33: {=INDEX(_xll.DUCKDB.EXEC($D$2,B33:C33),2)} -> BOOLEAN | G33: =IF(E33=F33,"PASS","FAIL") -> PASS | I33: FALSE | J33: {=INDEX(_xll.DUCKDB.EXEC($H$2,B33:C33),2)} -> FALSE | K33: =IF(ISNA(I33),IF(ISNA(J33),"PASS","FAIL"),IFERROR(IF(I33=J33,"PASS","FAIL"),"FAIL")) -> PASS
A34: 33 | B34: True/false in text | C34: true | E34: BOOLEAN | F34: {=INDEX(_xll.DUCKDB.EXEC($D$2,B34:C34),2)} -> BOOLEAN | G34: =IF(E34=F34,"PASS","FAIL") -> PASS | I34: TRUE | J34: {=INDEX(_xll.DUCKDB.EXEC($H$2,B34:C34),2)} -> TRUE | K34: =IF(ISNA(I34),IF(ISNA(J34),"PASS","FAIL"),IFERROR(IF(I34=J34,"PASS","FAIL"),"FAIL")) -> PASS
A35: 34 | B35: True/false in text | C35: false | E35: BOOLEAN | F35: {=INDEX(_xll.DUCKDB.EXEC($D$2,B35:C35),2)} -> BOOLEAN | G35: =IF(E35=F35,"PASS","FAIL") -> PASS | I35: FALSE | J35: {=INDEX(_xll.DUCKDB.EXEC($H$2,B35:C35),2)} -> FALSE | K35: =IF(ISNA(I35),IF(ISNA(J35),"PASS","FAIL"),IFERROR(IF(I35=J35,"PASS","FAIL"),"FAIL")) -> PASS
A36: 35 | B36: True/false in text | C36: T | E36: BOOLEAN | F36: {=INDEX(_xll.DUCKDB.EXEC($D$2,B36:C36),2)} -> BOOLEAN | G36: =IF(E36=F36,"PASS","FAIL") -> PASS | I36: TRUE | J36: {=INDEX(_xll.DUCKDB.EXEC($H$2,B36:C36),2)} -> TRUE | K36: =IF(ISNA(I36),IF(ISNA(J36),"PASS","FAIL"),IFERROR(IF(I36=J36,"PASS","FAIL"),"FAIL")) -> PASS
A37: 36 | B37: True/false in text | C37: F | E37: BOOLEAN | F37: {=INDEX(_xll.DUCKDB.EXEC($D$2,B37:C37),2)} -> BOOLEAN | G37: =IF(E37=F37,"PASS","FAIL") -> PASS | I37: FALSE | J37: {=INDEX(_xll.DUCKDB.EXEC($H$2,B37:C37),2)} -> FALSE | K37: =IF(ISNA(I37),IF(ISNA(J37),"PASS","FAIL"),IFERROR(IF(I37=J37,"PASS","FAIL"),"FAIL")) -> PASS
A38: 37 | B38: True/false in text | C38: t | E38: BOOLEAN | F38: {=INDEX(_xll.DUCKDB.EXEC($D$2,B38:C38),2)} -> BOOLEAN | G38: =IF(E38=F38,"PASS","FAIL") -> PASS | I38: TRUE | J38: {=INDEX(_xll.DUCKDB.EXEC($H$2,B38:C38),2)} -> TRUE | K38: =IF(ISNA(I38),IF(ISNA(J38),"PASS","FAIL"),IFERROR(IF(I38=J38,"PASS","FAIL"),"FAIL")) -> PASS
A39: 38 | B39: True/false in text | C39: f | E39: BOOLEAN | F39: {=INDEX(_xll.DUCKDB.EXEC($D$2,B39:C39),2)} -> BOOLEAN | G39: =IF(E39=F39,"PASS","FAIL") -> PASS | I39: FALSE | J39: {=INDEX(_xll.DUCKDB.EXEC($H$2,B39:C39),2)} -> FALSE | K39: =IF(ISNA(I39),IF(ISNA(J39),"PASS","FAIL"),IFERROR(IF(I39=J39,"PASS","FAIL"),"FAIL")) -> PASS
A40: 39 | B40: True/false in text with leading and trailing space | C40: TRUE | E40: BOOLEAN | F40: {=INDEX(_xll.DUCKDB.EXEC($D$2,B40:C40),2)} -> BOOLEAN | G40: =IF(E40=F40,"PASS","FAIL") -> PASS | I40: TRUE | J40: {=INDEX(_xll.DUCKDB.EXEC($H$2,B40:C40),2)} -> TRUE | K40: =IF(ISNA(I40),IF(ISNA(J40),"PASS","FAIL"),IFERROR(IF(I40=J40,"PASS","FAIL"),"FAIL")) -> PASS
...

Sheet INFERENCE_2
A1: ID | B1: Test Case | C1: Excel Values | D1: SQL | E1: Expected Inferred Type | F1: Actual Inferred Type | G1: Test Result
A2: 1 | B2: Integer | C2: 1 | D2: select column_type from (describe (from xlrange(1, header=false, sample=0))); | E2: INTEGER | F2: {=INDEX(_xll.DUCKDB.EXEC($D$2,C2:C3),2)} -> INTEGER | G2: =IF(E2=F2,"PASS","FAIL") -> PASS
A4: 2 | B4: Integer | E4: INTEGER | F4: {=INDEX(_xll.DUCKDB.EXEC($D$2,C4:C5),2)} -> INTEGER | G4: =IF(E4=F4,"PASS","FAIL") -> PASS
C5: 1
A6: 3 | B6: Integer | C6: 1 | E6: INTEGER | F6: {=INDEX(_xll.DUCKDB.EXEC($D$2,C6:C7),2)} -> INTEGER | G6: =IF(E6=F6,"PASS","FAIL") -> PASS
C7: 2
A8: 4 | B8: Double | C8: 1.2 | E8: DOUBLE | F8: {=INDEX(_xll.DUCKDB.EXEC($D$2,C8:C9),2)} -> DOUBLE | G8: =IF(E8=F8,"PASS","FAIL") -> PASS
A10: 5 | B10: Double | E10: DOUBLE | F10: {=INDEX(_xll.DUCKDB.EXEC($D$2,C10:C11),2)} -> DOUBLE | G10: =IF(E10=F10,"PASS","FAIL") -> PASS
C11: 1.2
A12: 6 | B12: Double | C12: 1.2 | E12: DOUBLE | F12: {=INDEX(_xll.DUCKDB.EXEC($D$2,C12:C13),2)} -> DOUBLE | G12: =IF(E12=F12,"PASS","FAIL") -> PASS
C13: 3.4
A14: 7 | B14: Boolean | C14: TRUE | E14: BOOLEAN | F14: {=INDEX(_xll.DUCKDB.EXEC($D$2,C14:C15),2)} -> BOOLEAN | G14: =IF(E14=F14,"PASS","FAIL") -> PASS
A16: 8 | B16: Boolean | C16: FALSE | E16: BOOLEAN | F16: {=INDEX(_xll.DUCKDB.EXEC($D$2,C16:C17),2)} -> BOOLEAN | G16: =IF(E16=F16,"PASS","FAIL") -> PASS
A18: 9 | B18: Boolean | C18: TRUE | E18: BOOLEAN | F18: {=INDEX(_xll.DUCKDB.EXEC($D$2,C18:C19),2)} -> BOOLEAN | G18: =IF(E18=F18,"PASS","FAIL") -> PASS
C19: FALSE
A20: 10 | B20: Boolean | C20: TRUE | E20: BOOLEAN | F20: {=INDEX(_xll.DUCKDB.EXEC($D$2,C20:C21),2)} -> BOOLEAN | G20: =IF(E20=F20,"PASS","FAIL") -> PASS
C21: 1
A22: 11 | B22: Boolean | C22: FALSE | E22: BOOLEAN | F22: {=INDEX(_xll.DUCKDB.EXEC($D$2,C22:C23),2)} -> BOOLEAN | G22: =IF(E22=F22,"PASS","FAIL") -> PASS
C23: 0
A24: 12 | B24: Varchar | C24: abc | E24: VARCHAR | F24: {=INDEX(_xll.DUCKDB.EXEC($D$2,C24:C25),2)} -> VARCHAR | G24: =IF(E24=F24,"PASS","FAIL") -> PASS
A26: 13 | B26: Varchar | E26: VARCHAR | F26: {=INDEX(_xll.DUCKDB.EXEC($D$2,C26:C27),2)} -> VARCHAR | G26: =IF(E26=F26,"PASS","FAIL") -> PASS
C27: abc
A28: 14 | B28: Varchar | C28: abc | E28: VARCHAR | F28: {=INDEX(_xll.DUCKDB.EXEC($D$2,C28:C29),2)} -> VARCHAR | G28: =IF(E28=F28,"PASS","FAIL") -> PASS
C29: abc
A30: 15 | B30: Integer -> Double | C30: 1 | E30: DOUBLE | F30: {=INDEX(_xll.DUCKDB.EXEC($D$2,C30:C31),2)} -> DOUBLE | G30: =IF(E30=F30,"PASS","FAIL") -> PASS
C31: 1.2
A32: 16 | B32: Integer -> Double -> Varchar | C32: 1 | E32: VARCHAR | F32: {=INDEX(_xll.DUCKDB.EXEC($D$2,C32:C34),2)} -> VARCHAR | G32: =IF(E32=F32,"PASS","FAIL") -> PASS
C33: 1.2
C34: abc
A35: 17 | B35: Integer -> Double -> Varchar | C35: 1 | E35: VARCHAR | F35: {=INDEX(_xll.DUCKDB.EXEC($D$2,C35:C37),2)} -> VARCHAR | G35: =IF(E35=F35,"PASS","FAIL") -> PASS
C36: 1.2
C37: TRUE
A38: 18 | B38: Integer -> Varchar | C38: 1 | E38: VARCHAR | F38: {=INDEX(_xll.DUCKDB.EXEC($D$2,C38:C39),2)} -> VARCHAR | G38: =IF(E38=F38,"PASS","FAIL") -> PASS
C39: abc
A40: 19 | B40: Integer -> Varchar | C40: 1 | E40: VARCHAR | F40: {=INDEX(_xll.DUCKDB.EXEC($D$2,C40:C41),2)} -> VARCHAR | G40: =IF(E40=F40,"PASS","FAIL") -> PASS
C41: FALSE
A42: 20 | B42: Double -> Varchar | C42: 1.2 | E42: VARCHAR | F42: {=INDEX(_xll.DUCKDB.EXEC($D$2,C42:C43),2)} -> VARCHAR | G42: =IF(E42=F42,"PASS","FAIL") -> PASS
C43: abc
A44: 21 | B44: Double -> Varchar | C44: 1 | E44: VARCHAR | F44: {=INDEX(_xll.DUCKDB.EXEC($D$2,C44:C45),2)} -> VARCHAR | G44: =IF(E44=F44,"PASS","FAIL") -> PASS
C45: FALSE

Sheet CONVERT
A1: ID | B1: Test Case | C1: Excel Values | D1: SQL | E1: Expect Result | F1: Actual Result | G1: Test Result
A2: 1 | B2: To integer | C2: 1 | D2: select * from xlrange(1, header=false, sample=1) | E2: 1 | F2: {=INDEX(_xll.DUCKDB.EXEC($D$2,C2:C3),3)} -> 1 | G2: =IF(E2=F2,"PASS","FAIL") -> PASS
C3: 1
A4: 2 | B4: To integer | C4: 1 | E4: 1 | F4: {=INDEX(_xll.DUCKDB.EXEC($D$2,C4:C5),3)} -> 1 | G4: =IF(E4=F4,"PASS","FAIL") -> PASS
C5: 1
A6: 3 | B6: To integer | C6: 1 | E6: 1 | F6: {=INDEX(_xll.DUCKDB.EXEC($D$2,C6:C7),3)} -> 1 | G6: =IF(E6=F6,"PASS","FAIL") -> PASS
C7: 1.0
A8: 4 | B8: To integer | C8: 1 | E8: 10 | F8: {=INDEX(_xll.DUCKDB.EXEC($D$2,C8:C9),3)} -> 10 | G8: =IF(E8=F8,"PASS","FAIL") -> PASS
C9: 1e1
A10: 5 | B10: To integer | C10: 1 | E10: 10 | F10: {=INDEX(_xll.DUCKDB.EXEC($D$2,C10:C11),3)} -> 10 | G10: =IF(E10=F10,"PASS","FAIL") -> PASS
C11: 1e1
A12: 6 | B12: To integer | C12: 1 | E12: Invalid Input Error | F12: {=_xll.DUCKDB.EXEC($D$2,C12:C13)} -> Invalid Input Error: Error scanning xlrange: Column #1, row 2: Failed to convert value to INTEGER. | G12: =IF(ISNA(E12),IF(ISNA(F12),"PASS","FAIL"),IFERROR(IF(E12=LEFT(F12,LEN(E12)),"PASS","FAIL"),"FAIL")) -> PASS
C13: abc
A14: 7 | B14: To integer | C14: 1 | E14: Invalid Input Error | F14: {=_xll.DUCKDB.EXEC($D$2,C14:C15)} -> Invalid Input Error: Error scanning xlrange: Column #1, row 2: Failed to convert value to INTEGER. | G14: =IF(ISNA(E14),IF(ISNA(F14),"PASS","FAIL"),IFERROR(IF(E14=LEFT(F14,LEN(E14)),"PASS","FAIL"),"FAIL")) -> PASS
C15: 1.2
A16: 8 | B16: To integer | C16: 1 | E16: Invalid Input Error | F16: {=_xll.DUCKDB.EXEC($D$2,C16:C17)} -> Invalid Input Error: Error scanning xlrange: Column #1, row 2: Failed to convert value to INTEGER. | G16: =IF(ISNA(E16),IF(ISNA(F16),"PASS","FAIL"),IFERROR(IF(E16=LEFT(F16,LEN(E16)),"PASS","FAIL"),"FAIL")) -> PASS
C17: 1.2
A18: 9 | B18: To integer | C18: 1 | E18: Invalid Input Error | F18: {=_xll.DUCKDB.EXEC($D$2,C18:C19)} -> Invalid Input Error: Error scanning xlrange: Column #1, row 2: Failed to convert value to INTEGER. | G18: =IF(ISNA(E18),IF(ISNA(F18),"PASS","FAIL"),IFERROR(IF(E18=LEFT(F18,LEN(E18)),"PASS","FAIL"),"FAIL")) -> PASS
C19: 1.2e-1
A20: 10 | B20: To integer | C20: 1 | E20: Invalid Input Error | F20: {=_xll.DUCKDB.EXEC($D$2,C20:C21)} -> Invalid Input Error: Error scanning xlrange: Column #1, row 2: Failed to convert value to INTEGER. | G20: =IF(ISNA(E20),IF(ISNA(F20),"PASS","FAIL"),IFERROR(IF(E20=LEFT(F20,LEN(E20)),"PASS","FAIL"),"FAIL")) -> PASS
C21: 1.2e-1
A22: 11 | B22: To integer | C22: 1 | E22: Invalid Input Error | F22: {=_xll.DUCKDB.EXEC($D$2,C22:C23)} -> Invalid Input Error: Error scanning xlrange: Column #1, row 2: Failed to convert value to INTEGER. | G22: =IF(ISNA(E22),IF(ISNA(F22),"PASS","FAIL"),IFERROR(IF(E22=LEFT(F22,LEN(E22)),"PASS","FAIL"),"FAIL")) -> PASS
C23: TRUE
A24: 12 | B24: To integer | C24: 1 | E24: Invalid Input Error | F24: {=_xll.DUCKDB.EXEC($D$2,C24:C25)} -> Invalid Input Error: Error scanning xlrange: Column #1, row 2: Failed to convert value to INTEGER. | G24: =IF(ISNA(E24),IF(ISNA(F24),"PASS","FAIL"),IFERROR(IF(E24=LEFT(F24,LEN(E24)),"PASS","FAIL"),"FAIL")) -> PASS
C25: TRUE
A26: 13 | B26: To integer | C26: 1 | E26: Invalid Input Error | F26: {=_xll.DUCKDB.EXEC($D$2,C26:C27)} -> Invalid Input Error: Error scanning xlrange: Column #1, row 2: Failed to convert value to INTEGER. | G26: =IF(ISNA(E26),IF(ISNA(F26),"PASS","FAIL"),IFERROR(IF(E26=LEFT(F26,LEN(E26)),"PASS","FAIL"),"FAIL")) -> PASS
C27: false
A28: 14 | B28: To integer | C28: 1 | E28: Invalid Input Error | F28: {=_xll.DUCKDB.EXEC($D$2,C28:C29)} -> Invalid Input Error: Error scanning xlrange: Column #1, row 2: Failed to convert value to INTEGER. | G28: =IF(ISNA(E28),IF(ISNA(F28),"PASS","FAIL"),IFERROR(IF(E28=LEFT(F28,LEN(E28)),"PASS","FAIL"),"FAIL")) -> PASS
C29: T
A30: 15 | B30: To integer | C30: 1 | E30: Invalid Input Error | F30: {=_xll.DUCKDB.EXEC($D$2,C30:C31)} -> Invalid Input Error: Error scanning xlrange: Column #1, row 2: Failed to convert value to INTEGER. | G30: =IF(ISNA(E30),IF(ISNA(F30),"PASS","FAIL"),IFERROR(IF(E30=LEFT(F30,LEN(E30)),"PASS","FAIL"),"FAIL")) -> PASS
C31: f
A32: 16 | B32: To integer | C32: 1 | E32: Invalid Input Error | F32: {=_xll.DUCKDB.EXEC($D$2,C32:C33)} -> Invalid Input Error: Error scanning xlrange: Column #1, row 2: Failed to convert value to INTEGER. | G32: =IF(ISNA(E32),IF(ISNA(F32),"PASS","FAIL"),IFERROR(IF(E32=LEFT(F32,LEN(E32)),"PASS","FAIL"),"FAIL")) -> PASS
C33: YES
A34: 17 | B34: To integer | C34: 1 | E34: Invalid Input Error | F34: {=_xll.DUCKDB.EXEC($D$2,C34:C35)} -> Invalid Input Error: Error scanning xlrange: Column #1, row 2: Failed to convert value to INTEGER. | G34: =IF(ISNA(E34),IF(ISNA(F34),"PASS","FAIL"),IFERROR(IF(E34=LEFT(F34,LEN(E34)),"PASS","FAIL"),"FAIL")) -> PASS
C35: no
A36: 18 | B36: To integer | C36: 1 | E36: Invalid Input Error | F36: {=_xll.DUCKDB.EXEC($D$2,C36:C37)} -> Invalid Input Error: Error scanning xlrange: Column #1, row 2: Failed to convert value to INTEGER. | G36: =IF(ISNA(E36),IF(ISNA(F36),"PASS","FAIL"),IFERROR(IF(E36=LEFT(F36,LEN(E36)),"PASS","FAIL"),"FAIL")) -> PASS
C37: no
A38: 19 | B38: To double | C38: 1.2 | E38: 3.4 | F38: {=INDEX(_xll.DUCKDB.EXEC($D$2,C38:C39),3)} -> 3.4 | G38: =IF(E38=F38,"PASS","FAIL") -> PASS
C39: 3.4
A40: 20 | B40: To double | C40: 1.2 | E40: 1 | F40: {=INDEX(_xll.DUCKDB.EXEC($D$2,C40:C41),3)} -> 1 | G40: =IF(E40=F40,"PASS","FAIL") -> PASS
...

Sheet XLRANGE OPTIONS
A1: TEST DATA 1 | B1: c1 | C1: c2 | D1: c3 | E1: c4 | F1: c5 | G1: c6 | I1: TEST DATA 2 | J1: a | K1: a | N1: b | O1: c
B2: 1 | C2: 1.2 | D2: FALSE | E2: abc | G2: =1/0 -> #DIV/0! | J2: 1 | K2: 1.2 | L2: FALSE | M2: abc | O2: =1/0 -> #DIV/0!
B3: 1.2 | C3: abc | D3: abc | E3: abc | J3: 1.2 | K3: abc | L3: abc | M3: abc
B4: abc | E4: abc | J4: abc | M4: abc
A6: TEST DATA 3 | B6: c1 | C6: c2 | D6: c3 | E6: c4 | F6: c5 | G6: c6
B7: 0001 | C7: 00001.2
B8: 1 | C8: 3.4
A11: ID | B11: Test Case | C11: SQL | D11: Expect Result | E11: Actual Result | F11: Test Result Detail | G11: Test Result
A12: 1 | B12: TEST DATA 1 sample = 1 | C12: select column_type from (describe (from xlrange(1, sample=1))) | D12: column_type | E12: {=_xll.DUCKDB.EXEC(C12,$B$1:$G$4)} -> column_type | F12: =IF(E12=D12,"PASS","FAIL") -> PASS | G12: =IF(COUNTA(F12:F18)=COUNTIF(F12:F18,"PASS"),"PASS","FAIL") -> PASS
D13: INTEGER | E13: INTEGER | F13: =IF(E13=D13,"PASS","FAIL") -> PASS
D14: DOUBLE | E14: DOUBLE | F14: =IF(E14=D14,"PASS","FAIL") -> PASS
D15: BOOLEAN | E15: BOOLEAN | F15: =IF(E15=D15,"PASS","FAIL") -> PASS
D16: VARCHAR | E16: VARCHAR | F16: =IF(E16=D16,"PASS","FAIL") -> PASS
D17: VARCHAR | E17: VARCHAR | F17: =IF(E17=D17,"PASS","FAIL") -> PASS
D18: VARCHAR | E18: VARCHAR | F18: =IF(E18=D18,"PASS","FAIL") -> PASS
A19: 2 | B19: TEST DATA 1 sample = 2 | C19: select column_type from (describe (from xlrange(1, sample=2))) | D19: column_type | E19: {=_xll.DUCKDB.EXEC(C19,$B$1:$G$4)} -> column_type | F19: =IF(E19=D19,"PASS","FAIL") -> PASS | G19: =IF(COUNTA(F19:F25)=COUNTIF(F19:F25,"PASS"),"PASS","FAIL") -> PASS
D20: DOUBLE | E20: DOUBLE | F20: =IF(E20=D20,"PASS","FAIL") -> PASS
D21: VARCHAR | E21: VARCHAR | F21: =IF(E21=D21,"PASS","FAIL") -> PASS
D22: VARCHAR | E22: VARCHAR | F22: =IF(E22=D22,"PASS","FAIL") -> PASS
D23: VARCHAR | E23: VARCHAR | F23: =IF(E23=D23,"PASS","FAIL") -> PASS
D24: VARCHAR | E24: VARCHAR | F24: =IF(E24=D24,"PASS","FAIL") -> PASS
D25: VARCHAR | E25: VARCHAR | F25: =IF(E25=D25,"PASS","FAIL") -> PASS
A26: 3 | B26: TEST DATA 1 sample = 0 | C26: select column_type from (describe (from xlrange(1, sample=0))) | D26: column_type | E26: {=_xll.DUCKDB.EXEC(C26,$B$1:$G$4)} -> column_type | F26: =IF(E26=D26,"PASS","FAIL") -> PASS | G26: =IF(COUNTA(F26:F32)=COUNTIF(F26:F32,"PASS"),"PASS","FAIL") -> PASS
D27: VARCHAR | E27: VARCHAR | F27: =IF(E27=D27,"PASS","FAIL") -> PASS
D28: VARCHAR | E28: VARCHAR | F28: =IF(E28=D28,"PASS","FAIL") -> PASS
D29: VARCHAR | E29: VARCHAR | F29: =IF(E29=D29,"PASS","FAIL") -> PASS
D30: VARCHAR | E30: VARCHAR | F30: =IF(E30=D30,"PASS","FAIL") -> PASS
D31: VARCHAR | E31: VARCHAR | F31: =IF(E31=D31,"PASS","FAIL") -> PASS
D32: VARCHAR | E32: VARCHAR | F32: =IF(E32=D32,"PASS","FAIL") -> PASS
A33: 4 | B33: TEST DATA 1 all_varchar=true | C33: select column_type from (describe (from xlrange(1, all_varchar=true))) | D33: column_type | E33: {=_xll.DUCKDB.EXEC(C33,$B$1:$G$4)} -> column_type | F33: =IF(E33=D33,"PASS","FAIL") -> PASS | G33: =IF(COUNTA(F33:F39)=COUNTIF(F33:F39,"PASS"),"PASS","FAIL") -> PASS
D34: VARCHAR | E34: VARCHAR | F34: =IF(E34=D34,"PASS","FAIL") -> PASS
D35: VARCHAR | E35: VARCHAR | F35: =IF(E35=D35,"PASS","FAIL") -> PASS
D36: VARCHAR | E36: VARCHAR | F36: =IF(E36=D36,"PASS","FAIL") -> PASS
D37: VARCHAR | E37: VARCHAR | F37: =IF(E37=D37,"PASS","FAIL") -> PASS
D38: VARCHAR | E38: VARCHAR | F38: =IF(E38=D38,"PASS","FAIL") -> PASS
D39: VARCHAR | E39: VARCHAR | F39: =IF(E39=D39,"PASS","FAIL") -> PASS
A40: 5 | B40: TEST DATA 2 header=false | C40: select column_name from (describe (from xlrange(1, sample=1, header=false))) | D40: column_name | E40: {=_xll.DUCKDB.EXEC(C40,$J$2:$O$4)} -> column_name | F40: =IF(E40=D40,"PASS","FAIL") -> PASS | G40: =IF(COUNTA(F40:F46)=COUNTIF(F40:F46,"PASS"),"PASS","FAIL") -> PASS
D41: column_0 | E41: column_0 | F41: =IF(E41=D41,"PASS","FAIL") -> PASS
D42: column_1 | E42: column_1 | F42: =IF(E42=D42,"PASS","FAIL") -> PASS
D43: column_2 | E43: column_2 | F43: =IF(E43=D43,"PASS","FAIL") -> PASS
...

Sheet SCALAR FUNCS
A1: ID | B1: Test case | C1: Excel Value | D1: SQL | E1: Expected Result | F1: Actual Result | G1: Test Result
A2: 1 | B2: Date | C2: 46387 | D2: select xldate(?) + interval 6 month | E2: 46568 | F2: {=INDEX(_xll.DUCKDB.EXEC(D2,C2),2)} -> 46568 | G2: =IF(F2=E2,"PASS","FAIL") -> PASS
A3: 2 | B3: Time | C3: 0.39635417 | D3: select xltime(?) - interval 10 minutes | E3: 0.38940972 | F3: {=INDEX(_xll.DUCKDB.EXEC(D3,C3),2)} -> 0.38940972 | G3: =IF(F3=E3,"PASS","FAIL") -> PASS
A4: 3 | B4: Date and time | C4: 46387.396 | D4: select xldatetime(?) + interval 7 days | E4: 46394.396 | F4: {=INDEX(_xll.DUCKDB.EXEC(D4,C4),2)} -> 46394.396 | G4: =IF(F4=E4,"PASS","FAIL") -> PASS

Sheet EXECX-A-AX-ASYNC
A1: ID | B1: Test Case | C1: Initialization SQL | D1: Main SQL | E1: Expected Result | F1: Actual Result | G1: Test Result
A2: 1 | B2: DUCKDB.EXECX | C2: create macro test_macro(x) as x; | D2: select test_macro(1); | E2: 1 | F2: {=INDEX(_xll.DUCKDB.EXECX(C2,D2),2)} -> 1 | G2: =IF(F2=E2,"PASS","FAIL") -> PASS
A3: 2 | B3: DUCKDB.EXECX.ASYNC | C3: create macro test_macro(x) as x; | D3: select test_macro(1); | E3: 1 | F3: {=INDEX(_xll.DUCKDB.EXECX.ASYNC(C3,D3),2)} -> 1 | G3: =IF(F3=E3,"PASS","FAIL") -> PASS
A4: 3 | B4: DUCKDB.EXECA | D4: select 1; | E4: 1 | F4: {=INDEX(_xll.DUCKDB.EXECA(,D4),2)} -> 1 | G4: =IF(F4=E4,"PASS","FAIL") -> PASS
A5: 4 | B5: DUCKDB.EXECA.ASYNC | D5: select 1; | E5: 1 | F5: {=INDEX(_xll.DUCKDB.EXECA.ASYNC(,D5),2)} -> 1 | G5: =IF(F5=E5,"PASS","FAIL") -> PASS
A6: 5 | B6: DUCKDB.EXECAX | C6: create macro test_macro(x) as x; | D6: select test_macro(1); | E6: 1 | F6: {=INDEX(_xll.DUCKDB.EXECAX(,C6,D6),2)} -> 1 | G6: =IF(F6=E6,"PASS","FAIL") -> PASS
A7: 6 | B7: DUCKDB.EXECAX.ASYNC | C7: create macro test_macro(x) as x; | D7: select test_macro(1); | E7: 1 | F7: {=INDEX(_xll.DUCKDB.EXECAX.ASYNC(,C7,D7),2)} -> 1 | G7: =IF(F7=E7,"PASS","FAIL") -> PASS
A8: 7 | B8: DUCKDB.EXEC.ASYNC | D8: select 1; | E8: 1 | F8: {=INDEX(_xll.DUCKDB.EXEC.ASYNC(D8),2)} -> 1 | G8: =IF(F8=E8,"PASS","FAIL") -> PASS
